
----------
2018-12-11T13:33:58.131616+00:00
----------
Potential issues with this project:
  * anaconda-project.yml: No command runs notebook 0-IntroPython (1).ipynb

Server available at 0.0.0.0:44318
127.0.0.1 - - [11/Dec/2018 13:33:59] "GET /api/anaconda-project/proxy/project/my-command HTTP/1.1" 200 -
----------------------------------------
Exception happened during processing of request from ('127.0.0.1', 52462)
Traceback (most recent call last):
  File "/opt/continuum/anaconda/envs/anaconda50_py36/lib/python3.6/socketserver.py", line 317, in _handle_request_noblock
    self.process_request(request, client_address)
  File "/opt/continuum/anaconda/envs/anaconda50_py36/lib/python3.6/socketserver.py", line 348, in process_request
    self.finish_request(request, client_address)
  File "/opt/continuum/anaconda/envs/anaconda50_py36/lib/python3.6/socketserver.py", line 361, in finish_request
    self.RequestHandlerClass(request, client_address, self)
  File "/opt/continuum/anaconda/envs/anaconda50_py36/lib/python3.6/socketserver.py", line 696, in __init__
    self.handle()
  File "/opt/continuum/anaconda/envs/anaconda50_py36/lib/python3.6/http/server.py", line 418, in handle
    self.handle_one_request()
  File "/opt/continuum/anaconda/envs/anaconda50_py36/lib/python3.6/http/server.py", line 406, in handle_one_request
    method()
  File "/opt/continuum/project/testing2.py", line 27, in do_GET
    dirlist = os.listdir('~/var/run/secrets/user_credentials/')
FileNotFoundError: [Errno 2] No such file or directory: '~/var/run/secrets/user_credentials/'
----------------------------------------
127.0.0.1 - - [11/Dec/2018 13:34:00] "GET /api/anaconda-project/proxy/project/my-command HTTP/1.1" 200 -
----------------------------------------
Exception happened during processing of request from ('127.0.0.1', 52562)
Traceback (most recent call last):
  File "/opt/continuum/anaconda/envs/anaconda50_py36/lib/python3.6/socketserver.py", line 317, in _handle_request_noblock
    self.process_request(request, client_address)
  File "/opt/continuum/anaconda/envs/anaconda50_py36/lib/python3.6/socketserver.py", line 348, in process_request
    self.finish_request(request, client_address)
  File "/opt/continuum/anaconda/envs/anaconda50_py36/lib/python3.6/socketserver.py", line 361, in finish_request
    self.RequestHandlerClass(request, client_address, self)
  File "/opt/continuum/anaconda/envs/anaconda50_py36/lib/python3.6/socketserver.py", line 696, in __init__
    self.handle()
  File "/opt/continuum/anaconda/envs/anaconda50_py36/lib/python3.6/http/server.py", line 418, in handle
    self.handle_one_request()
  File "/opt/continuum/anaconda/envs/anaconda50_py36/lib/python3.6/http/server.py", line 406, in handle_one_request
    method()
  File "/opt/continuum/project/testing2.py", line 27, in do_GET
    dirlist = os.listdir('~/var/run/secrets/user_credentials/')
FileNotFoundError: [Errno 2] No such file or directory: '~/var/run/secrets/user_credentials/'
----------------------------------------
127.0.0.1 - - [11/Dec/2018 13:34:02] "GET /api/anaconda-project/proxy/project/my-command HTTP/1.1" 200 -
----------------------------------------
Exception happened during processing of request from ('127.0.0.1', 52820)
Traceback (most recent call last):
  File "/opt/continuum/anaconda/envs/anaconda50_py36/lib/python3.6/socketserver.py", line 317, in _handle_request_noblock
    self.process_request(request, client_address)
  File "/opt/continuum/anaconda/envs/anaconda50_py36/lib/python3.6/socketserver.py", line 348, in process_request
    self.finish_request(request, client_address)
  File "/opt/continuum/anaconda/envs/anaconda50_py36/lib/python3.6/socketserver.py", line 361, in finish_request
    self.RequestHandlerClass(request, client_address, self)
  File "/opt/continuum/anaconda/envs/anaconda50_py36/lib/python3.6/socketserver.py", line 696, in __init__
    self.handle()
  File "/opt/continuum/anaconda/envs/anaconda50_py36/lib/python3.6/http/server.py", line 418, in handle
    self.handle_one_request()
  File "/opt/continuum/anaconda/envs/anaconda50_py36/lib/python3.6/http/server.py", line 406, in handle_one_request
    method()
  File "/opt/continuum/project/testing2.py", line 27, in do_GET
    dirlist = os.listdir('~/var/run/secrets/user_credentials/')
FileNotFoundError: [Errno 2] No such file or directory: '~/var/run/secrets/user_credentials/'
----------------------------------------
